Workbook

Sheet README
A1: Indian Food Nutrition Database
A2: Calories, protein, carbs, fat, fibre, sugar and sodium for Indian dishes - per 100 g/ml and per Small / Medium / Large and Half / Full plate portion.
A4: What's inside
A5: Dish Database | B5: =COUNTA('Dish Database'!A2:A586)&" dishes, per 100 g/ml + portion sizes + kcal per portion (filter by category, region, veg/non-veg, meal type)" -> 585 dishes, per 100 g/ml + portion sizes + kcal per portion (filter by category, region, veg/non-veg, meal type)
A6: Portion Nutrition | B6: =COUNTA('Portion Nutrition'!A2:A2170)&" rows: every dish x every portion size, with all macros (best sheet for logging/importing)" -> 2169 rows: every dish x every portion size, with all macros (best sheet for logging/importing)
A7: Meal Combos & Thalis | B7: 32 ready-made meals (idli sambar, chole bhature, thalis, sadya...) built from the database - editable
A8: Portion Guide | B8: Exactly what Small / Medium / Large / Half / Full mean for each type of dish
A9: INDB Full Nutrients | B9: All 1014 recipes from the Indian Nutrient Databank (2024) with 35 nutrients incl. vitamins & minerals, plus quality flags
A11: Coverage
A12: Hot beverages, cold drinks & sharbat, all common fruit juices, vegetable juices, lassi (sweet, salted, mango...) & chaas, milkshakes, North & West breakfast, South Indian tiffin, breads, rice/pulao/khichdi, biryani, dals, veg gravies, dry sabzi, non-veg curries (chicken, mutton, fish, prawn, egg), veg & non-veg starters/kebabs, snacks & fritters, street food & chaat, Indo-Chinese, soups, raita/salad/curd, chutneys/pickles/papad, namkeen, mithai, kheer/halwa/ice cream, and add-ons (ghee, oil, sugar, butter...).
A14: How the numbers were built
A15: 1. Per-100 g values are for the dish AS SERVED (cooked, with typical oil/ghee/sugar). Drinks and soups are per 100 ml.
A16: 2. Energy is calculated from the macros with Atwater factors: 4 x protein + 4 x (carbs - fibre) + 9 x fat + 2 x fibre. Carbs are TOTAL carbs (net carbs = carbs - fibre).
A17: 3. Where the Indian Nutrient Databank (INDB, 2024; built on ICMR-NIN IFCT 2017) has the same dish and its value passed quality checks, the estimate was cross-checked against it ("Cross-check vs INDB" column). Within 20% = Confidence "High".
A18: 4. Juices, milk, eggs, rice, bread and add-ons use single-ingredient composition data (USDA FoodData Central / IFCT 2017). Fresh juices assume NO added sugar.
A19: 5. Other dishes are typical-recipe estimates compiled from standard ingredient composition data - Confidence "Medium". Real dishes vary by ±15-30% mainly with oil, ghee, cream and sugar.
A21: Important findings about INDB (why it is not copied blindly)
A22: Deep-fried recipes | B22: =COUNTIF('INDB Full Nutrients'!AL2:AL1015,"*Deep-frying*")&" INDB recipes appear to count the full frying oil (e.g. samosa ~577, pakora ~675, poori ~738 kcal/100 g). Realistic values are ~250-330." -> 113 INDB recipes appear to count the full frying oil (e.g. samosa ~577, pakora ~675, poori ~738 kcal/100 g). Realistic values are ~250-330.
A23: Whole-recipe servings | B23: =COUNTIF('INDB Full Nutrients'!AL2:AL1015,"*whole recipe*")&" INDB recipes list a 'serving' over 1,200 kcal - the serving is effectively the whole batch." -> 84 INDB recipes list a 'serving' over 1,200 kcal - the serving is effectively the whole batch.
A24: Weight basis | B24: Some INDB per-100 g values include cooking/boiling water (boiled egg 45 kcal/100 g) or exclude it (poha 295, plain dosa 381). INDB home-science recipes are also lighter than typical home/restaurant cooking.
A26: Quick adjustments
A27: +1 tsp oil or ghee = +45 kcal, +5 g fat | +1 tsp butter = +36 kcal | +1 tsp sugar = +20 kcal, +5 g carbs | +1 tbsp fresh cream = +37 kcal | Shop juices usually add 2-4 tsp sugar per glass.
A29: Colour legend
A30: Blue numbers = source inputs you can edit (per-100 g values, portion weights, combo quantities). Black = formulas; everything recalculates.
A32: Sources
A33: Vijayakumar et al. (2024) Development of an Indian Food Composition Database, Current Developments in Nutrition - https://www.ncbi.nlm.nih.gov/pmc/articles/PMC11277795/
A34: INDB data files (Indian-Nutrient-Databank-INDB-, GitHub, lindsayjaacks) - https://github.com/lindsayjaacks/Indian-Nutrient-Databank-INDB- | Anuvaad INDB portal - https://www.anuvaad.org.in/indian-nutrient-databank/
A35: Longvah T. et al. (2017) Indian Food Composition Tables (IFCT 2017), ICMR-National Institute of Nutrition, Hyderabad.
A36: USDA FoodData Central (juices, milk, eggs, bread, rice reference values).
A38: Disclaimer
A39: Estimates for everyday tracking, not lab analysis. For medical diets (diabetes, kidney disease, etc.) confirm with a registered dietitian. Sodium values are approximate - restaurant food is often saltier.
A41: Dishes per category
A42: Hot Beverages | B42: =COUNTIF('Dish Database'!D2:D586,A42) -> 15
A43: Cold Beverages & Sharbat | B43: =COUNTIF('Dish Database'!D2:D586,A43) -> 23
A44: Fruit Juices | B44: =COUNTIF('Dish Database'!D2:D586,A44) -> 23
A45: Vegetable Juices | B45: =COUNTIF('Dish Database'!D2:D586,A45) -> 10
A46: Lassi & Buttermilk | B46: =COUNTIF('Dish Database'!D2:D586,A46) -> 10
A47: Milkshakes & Milk | B47: =COUNTIF('Dish Database'!D2:D586,A47) -> 12
A48: Breakfast - North & West | B48: =COUNTIF('Dish Database'!D2:D586,A48) -> 44
A49: Breakfast - South | B49: =COUNTIF('Dish Database'!D2:D586,A49) -> 36
...

Sheet Dish Database
A1: ID | B1: Dish | C1: Also known as | D1: Category | E1: Region | F1: Veg / Egg / Non-Veg | G1: Vegan | H1: Meal type | I1: Unit | J1: Energy (kcal) per 100 | K1: Protein (g) per 100 | L1: Carbs (g) per 100 | M1: Fat (g) per 100 | N1: Fibre (g) per 100 | O1: Sugar (g) per 100 | P1: Sodium (mg) per 100 | Q1: Small (g/ml) | R1: Medium (g/ml) | S1: Large (g/ml) | T1: Half plate (g) | U1: Full plate (g) | V1: kcal - Small | W1: kcal - Medium | X1: kcal - Large | Y1: kcal - Half plate | Z1: kcal - Full plate | AA1: Confidence | AB1: Basis | AC1: INDB code | AD1: INDB kcal per 100 | AE1: Cross-check vs INDB | AF1: Notes
A2: D001 | B2: Masala chai (milk + sugar) | C2: Tea, adrak chai, chai | D2: Hot Beverages | E2: Pan-India | F2: Veg | H2: Beverage | I2: ml | J2: =4*K2+4*(L2-N2)+9*M2+2*N2 -> 55.5 | K2: 1.6 | L2: 8.9 | M2: 1.5 | N2: 0 | O2: 8.9 | P2: 22 | Q2: 75 | R2: 150 | S2: 250 | V2: =IF(Q2="","",J2*Q2/100) -> 41.625 | W2: =IF(R2="","",J2*R2/100) -> 83.25 | X2: =IF(S2="","",J2*S2/100) -> 138.75 | Y2: =IF(T2="","",J2*T2/100) | Z2: =IF(U2="","",J2*U2/100) | AA2: Medium | AB2: Typical-recipe estimate (IFCT 2017 / USDA FDC ingredient data) | AC2: ASC001 | AD2: =IF(AC2="","",IFERROR(INDEX('INDB Full Nutrients'!$D:$D,MATCH(AC2,'INDB Full Nutrients'!$A:$A,0)),"")) -> 16.144299 | AE2: INDB 16 kcal/100 g (+244%) - INDB lower: lighter/thinner recipe, or cooking water counted in weight | AF2: INDB recipe has no added sugar; this assumes ~2 tsp sugar per 150 ml cup, toned milk ~50%
A3: D002 | B3: Tea with milk, no sugar | C3: Chai without sugar | D3: Hot Beverages | E3: Pan-India | F3: Veg | H3: Beverage | I3: ml | J3: =4*K3+4*(L3-N3)+9*M3+2*N3 -> 29.5 | K3: 1.6 | L3: 2.4 | M3: 1.5 | N3: 0 | O3: 2.4 | P3: 22 | Q3: 75 | R3: 150 | S3: 250 | V3: =IF(Q3="","",J3*Q3/100) -> 22.125 | W3: =IF(R3="","",J3*R3/100) -> 44.25 | X3: =IF(S3="","",J3*S3/100) -> 73.75 | Y3: =IF(T3="","",J3*T3/100) | Z3: =IF(U3="","",J3*U3/100) | AA3: Medium | AB3: Typical-recipe estimate (IFCT 2017 / USDA FDC ingredient data) | AD3: =IF(AC3="","",IFERROR(INDEX('INDB Full Nutrients'!$D:$D,MATCH(AC3,'INDB Full Nutrients'!$A:$A,0)),""))
A4: D003 | B4: Cutting chai (strong, extra milk & sugar) | C4: Tapri chai | D4: Hot Beverages | E4: West | F4: Veg | H4: Beverage | I4: ml | J4: =4*K4+4*(L4-N4)+9*M4+2*N4 -> 68 | K4: 2 | L4: 10.5 | M4: 2 | N4: 0 | O4: 10.5 | P4: 28 | Q4: 75 | R4: 150 | S4: 250 | V4: =IF(Q4="","",J4*Q4/100) -> 51 | W4: =IF(R4="","",J4*R4/100) -> 102 | X4: =IF(S4="","",J4*S4/100) -> 170 | Y4: =IF(T4="","",J4*T4/100) | Z4: =IF(U4="","",J4*U4/100) | AA4: Medium | AB4: Typical-recipe estimate (IFCT 2017 / USDA FDC ingredient data) | AD4: =IF(AC4="","",IFERROR(INDEX('INDB Full Nutrients'!$D:$D,MATCH(AC4,'INDB Full Nutrients'!$A:$A,0)),"")) | AF4: Street style
A5: D004 | B5: Irani chai | C5: Hyderabadi Irani chai | D5: Hot Beverages | E5: South | F5: Veg | H5: Beverage | I5: ml | J5: =4*K5+4*(L5-N5)+9*M5+2*N5 -> 85 | K5: 2.5 | L5: 12 | M5: 3 | N5: 0 | O5: 12 | P5: 35 | Q5: 75 | R5: 150 | S5: 250 | V5: =IF(Q5="","",J5*Q5/100) -> 63.75 | W5: =IF(R5="","",J5*R5/100) -> 127.5 | X5: =IF(S5="","",J5*S5/100) -> 212.5 | Y5: =IF(T5="","",J5*T5/100) | Z5: =IF(U5="","",J5*U5/100) | AA5: Medium | AB5: Typical-recipe estimate (IFCT 2017 / USDA FDC ingredient data) | AD5: =IF(AC5="","",IFERROR(INDEX('INDB Full Nutrients'!$D:$D,MATCH(AC5,'INDB Full Nutrients'!$A:$A,0)),"")) | AF5: Made with khoa/condensed milk
A6: D005 | B6: Black tea, no sugar | C6: Kali chai, lal chai | D6: Hot Beverages | E6: Pan-India | F6: Veg | G6: Yes | H6: Beverage | I6: ml | J6: =4*K6+4*(L6-N6)+9*M6+2*N6 -> 1.2 | K6: 0 | L6: 0.3 | M6: 0 | N6: 0 | O6: 0 | P6: 3 | Q6: 75 | R6: 150 | S6: 250 | V6: =IF(Q6="","",J6*Q6/100) -> 0.9 | W6: =IF(R6="","",J6*R6/100) -> 1.8 | X6: =IF(S6="","",J6*S6/100) -> 3 | Y6: =IF(T6="","",J6*T6/100) | Z6: =IF(U6="","",J6*U6/100) | AA6: High | AB6: Ingredient composition data (USDA FDC / IFCT 2017) | AD6: =IF(AC6="","",IFERROR(INDEX('INDB Full Nutrients'!$D:$D,MATCH(AC6,'INDB Full Nutrients'!$A:$A,0)),""))
A7: D006 | B7: Lemon tea with sugar | C7: Nimbu chai | D7: Hot Beverages | E7: Pan-India | F7: Veg | G7: Yes | H7: Beverage | I7: ml | J7: =4*K7+4*(L7-N7)+9*M7+2*N7 -> 20 | K7: 0 | L7: 5 | M7: 0 | N7: 0 | O7: 5 | P7: 3 | Q7: 75 | R7: 150 | S7: 250 | V7: =IF(Q7="","",J7*Q7/100) -> 15 | W7: =IF(R7="","",J7*R7/100) -> 30 | X7: =IF(S7="","",J7*S7/100) -> 50 | Y7: =IF(T7="","",J7*T7/100) | Z7: =IF(U7="","",J7*U7/100) | AA7: Medium | AB7: Typical-recipe estimate (IFCT 2017 / USDA FDC ingredient data) | AD7: =IF(AC7="","",IFERROR(INDEX('INDB Full Nutrients'!$D:$D,MATCH(AC7,'INDB Full Nutrients'!$A:$A,0)),""))
A8: D007 | B8: Green tea, no sugar | D8: Hot Beverages | E8: Pan-India | F8: Veg | G8: Yes | H8: Beverage | I8: ml | J8: =4*K8+4*(L8-N8)+9*M8+2*N8 -> 0.8 | K8: 0.2 | L8: 0 | M8: 0 | N8: 0 | O8: 0 | P8: 1 | Q8: 75 | R8: 150 | S8: 250 | V8: =IF(Q8="","",J8*Q8/100) -> 0.6 | W8: =IF(R8="","",J8*R8/100) -> 1.2 | X8: =IF(S8="","",J8*S8/100) -> 2 | Y8: =IF(T8="","",J8*T8/100) | Z8: =IF(U8="","",J8*U8/100) | AA8: High | AB8: Ingredient composition data (USDA FDC / IFCT 2017) | AD8: =IF(AC8="","",IFERROR(INDEX('INDB Full Nutrients'!$D:$D,MATCH(AC8,'INDB Full Nutrients'!$A:$A,0)),""))
A9: D008 | B9: South Indian filter coffee (milk + sugar) | C9: Kaapi, degree coffee | D9: Hot Beverages | E9: South | F9: Veg | H9: Beverage | I9: ml | J9: =4*K9+4*(L9-N9)+9*M9+2*N9 -> 70.9 | K9: 2.6 | L9: 9.5 | M9: 2.5 | N9: 0 | O9: 9.5 | P9: 35 | Q9: 75 | R9: 150 | S9: 250 | V9: =IF(Q9="","",J9*Q9/100) -> 53.175 | W9: =IF(R9="","",J9*R9/100) -> 106.35 | X9: =IF(S9="","",J9*S9/100) -> 177.25 | Y9: =IF(T9="","",J9*T9/100) | Z9: =IF(U9="","",J9*U9/100) | AA9: Medium | AB9: Typical-recipe estimate (IFCT 2017 / USDA FDC ingredient data) | AD9: =IF(AC9="","",IFERROR(INDEX('INDB Full Nutrients'!$D:$D,MATCH(AC9,'INDB Full Nutrients'!$A:$A,0)),"")) | AF9: Mostly milk, ~2 tsp sugar per 150 ml
A10: D009 | B10: Instant coffee with milk & sugar | C10: Nescafe/Bru coffee | D10: Hot Beverages | E10: Pan-India | F10: Veg | H10: Beverage | I10: ml | J10: =4*K10+4*(L10-N10)+9*M10+2*N10 -> 74.4 | K10: 2.8 | L10: 9.5 | M10: 2.8 | N10: 0 | O10: 9.5 | P10: 40 | Q10: 75 | R10: 150 | S10: 250 | V10: =IF(Q10="","",J10*Q10/100) -> 55.8 | W10: =IF(R10="","",J10*R10/100) -> 111.6 | X10: =IF(S10="","",J10*S10/100) -> 186 | Y10: =IF(T10="","",J10*T10/100) | Z10: =IF(U10="","",J10*U10/100) | AA10: Medium | AB10: Typical-recipe estimate (IFCT 2017 / USDA FDC ingredient data) | AC10: ASC002 | AD10: =IF(AC10="","",IFERROR(INDEX('INDB Full Nutrients'!$D:$D,MATCH(AC10,'INDB Full Nutrients'!$A:$A,0)),"")) -> 23.155832 | AE10: INDB 23 kcal/100 g (+221%) - INDB lower: lighter/thinner recipe, or cooking water counted in weight
A11: D010 | B11: Black coffee, no sugar | C11: Americano | D11: Hot Beverages | E11: Pan-India | F11: Veg | G11: Yes | H11: Beverage | I11: ml | J11: =4*K11+4*(L11-N11)+9*M11+2*N11 -> 0.8 | K11: 0.1 | L11: 0.1 | M11: 0 | N11: 0 | O11: 0 | P11: 2 | Q11: 75 | R11: 150 | S11: 250 | V11: =IF(Q11="","",J11*Q11/100) -> 0.6 | W11: =IF(R11="","",J11*R11/100) -> 1.2 | X11: =IF(S11="","",J11*S11/100) -> 2 | Y11: =IF(T11="","",J11*T11/100) | Z11: =IF(U11="","",J11*U11/100) | AA11: High | AB11: Ingredient composition data (USDA FDC / IFCT 2017) | AD11: =IF(AC11="","",IFERROR(INDEX('INDB Full Nutrients'!$D:$D,MATCH(AC11,'INDB Full Nutrients'!$A:$A,0)),""))
A12: D011 | B12: Hot chocolate / cocoa milk | C12: Bournvita/Horlicks style malted milk | D12: Hot Beverages | E12: Pan-India | F12: Veg | H12: Beverage | I12: ml | J12: =4*K12+4*(L12-N12)+9*M12+2*N12 -> 93.1 | K12: 3.2 | L12: 12.5 | M12: 3.5 | N12: 0.6 | O12: 11 | P12: 50 | Q12: 75 | R12: 150 | S12: 250 | V12: =IF(Q12="","",J12*Q12/100) -> 69.825 | W12: =IF(R12="","",J12*R12/100) -> 139.65 | X12: =IF(S12="","",J12*S12/100) -> 232.75 | Y12: =IF(T12="","",J12*T12/100) | Z12: =IF(U12="","",J12*U12/100) | AA12: High | AB12: Agrees with INDB 2024 standard recipe (within 20%) | AC12: BFP011 | AD12: =IF(AC12="","",IFERROR(INDEX('INDB Full Nutrients'!$D:$D,MATCH(AC12,'INDB Full Nutrients'!$A:$A,0)),"")) -> 90.005775 | AE12: INDB 90 kcal/100 g (+3%)
A13: D012 | B13: Haldi doodh (turmeric milk) | C13: Golden milk | D13: Hot Beverages | E13: Pan-India | F13: Veg | H13: Beverage | I13: ml | J13: =4*K13+4*(L13-N13)+9*M13+2*N13 -> 73.4 | K13: 3.2 | L13: 7.5 | M13: 3.4 | N13: 0 | O13: 7.3 | P13: 43 | Q13: 150 | R13: 200 | S13: 300 | V13: =IF(Q13="","",J13*Q13/100) -> 110.1 | W13: =IF(R13="","",J13*R13/100) -> 146.8 | X13: =IF(S13="","",J13*S13/100) -> 220.2 | Y13: =IF(T13="","",J13*T13/100) | Z13: =IF(U13="","",J13*U13/100) | AA13: Medium | AB13: Typical-recipe estimate (IFCT 2017 / USDA FDC ingredient data) | AD13: =IF(AC13="","",IFERROR(INDEX('INDB Full Nutrients'!$D:$D,MATCH(AC13,'INDB Full Nutrients'!$A:$A,0)),"")) | AF13: Whole milk, little sugar/jaggery
A14: D013 | B14: Badam milk (hot or cold) | C14: Almond milk drink | D14: Hot Beverages | E14: South | F14: Veg | H14: Beverage | I14: ml | J14: =4*K14+4*(L14-N14)+9*M14+2*N14 -> 102.9 | K14: 3.8 | L14: 12 | M14: 4.5 | N14: 0.4 | O14: 11.5 | P14: 42 | Q14: 150 | R14: 200 | S14: 300 | V14: =IF(Q14="","",J14*Q14/100) -> 154.35 | W14: =IF(R14="","",J14*R14/100) -> 205.8 | X14: =IF(S14="","",J14*S14/100) -> 308.7 | Y14: =IF(T14="","",J14*T14/100) | Z14: =IF(U14="","",J14*U14/100) | AA14: Medium | AB14: Typical-recipe estimate (IFCT 2017 / USDA FDC ingredient data) | AD14: =IF(AC14="","",IFERROR(INDEX('INDB Full Nutrients'!$D:$D,MATCH(AC14,'INDB Full Nutrients'!$A:$A,0)),"")) | AF14: With sugar and ground almonds
A15: D014 | B15: Kesar doodh (saffron milk) | C15: Kesariya doodh | D15: Hot Beverages | E15: North | F15: Veg | H15: Beverage | I15: ml | J15: =4*K15+4*(L15-N15)+9*M15+2*N15 -> 84.7 | K15: 3.3 | L15: 10 | M15: 3.5 | N15: 0 | O15: 9.5 | P15: 42 | Q15: 150 | R15: 200 | S15: 300 | V15: =IF(Q15="","",J15*Q15/100) -> 127.05 | W15: =IF(R15="","",J15*R15/100) -> 169.4 | X15: =IF(S15="","",J15*S15/100) -> 254.1 | Y15: =IF(T15="","",J15*T15/100) | Z15: =IF(U15="","",J15*U15/100) | AA15: High | AB15: Agrees with INDB 2024 standard recipe (within 20%) | AC15: OSR010 | AD15: =IF(AC15="","",IFERROR(INDEX('INDB Full Nutrients'!$D:$D,MATCH(AC15,'INDB Full Nutrients'!$A:$A,0)),"")) -> 102.18104 | AE15: INDB 102 kcal/100 g (-17%)
A16: D015 | B16: Kashmiri kahwa | C16: Kehwa | D16: Hot Beverages | E16: North | F16: Veg | G16: Yes | H16: Beverage | I16: ml | J16: =4*K16+4*(L16-N16)+9*M16+2*N16 -> 26.2 | K16: 0.3 | L16: 4.5 | M16: 0.8 | N16: 0.1 | O16: 4.2 | P16: 3 | Q16: 75 | R16: 150 | S16: 250 | V16: =IF(Q16="","",J16*Q16/100) -> 19.65 | W16: =IF(R16="","",J16*R16/100) -> 39.3 | X16: =IF(S16="","",J16*S16/100) -> 65.5 | Y16: =IF(T16="","",J16*T16/100) | Z16: =IF(U16="","",J16*U16/100) | AA16: High | AB16: Agrees with INDB 2024 standard recipe (within 20%) | AC16: BFP007 | AD16: =IF(AC16="","",IFERROR(INDEX('INDB Full Nutrients'!$D:$D,MATCH(AC16,'INDB Full Nutrients'!$A:$A,0)),"")) -> 24.903666 | AE16: INDB 25 kcal/100 g (+5%) | AF16: With sugar/honey and almond slivers
A17: D016 | B17: Nimbu pani - sweet | C17: Lemonade, shikanji (sweet) | D17: Cold Beverages & Sharbat | E17: Pan-India | F17: Veg | G17: Yes | H17: Beverage | I17: ml | J17: =4*K17+4*(L17-N17)+9*M17+2*N17 -> 26.3 | K17: 0.1 | L17: 6.5 | M17: 0 | N17: 0.05 | O17: 6.2 | P17: 5 | Q17: 150 | R17: 250 | S17: 350 | V17: =IF(Q17="","",J17*Q17/100) -> 39.45 | W17: =IF(R17="","",J17*R17/100) -> 65.75 | X17: =IF(S17="","",J17*S17/100) -> 92.05 | Y17: =IF(T17="","",J17*T17/100) | Z17: =IF(U17="","",J17*U17/100) | AA17: Medium | AB17: Typical-recipe estimate (IFCT 2017 / USDA FDC ingredient data) | AC17: ASC008 | AD17: =IF(AC17="","",IFERROR(INDEX('INDB Full Nutrients'!$D:$D,MATCH(AC17,'INDB Full Nutrients'!$A:$A,0)),"")) -> 20.798983 | AE17: INDB 21 kcal/100 g (+26%) - INDB lower: lighter/thinner recipe, or cooking water counted in weight
A18: D017 | B18: Nimbu pani - sweet & salty | C18: Shikanji, masala lemonade | D18: Cold Beverages & Sharbat | E18: North | F18: Veg | G18: Yes | H18: Beverage | I18: ml | J18: =4*K18+4*(L18-N18)+9*M18+2*N18 -> 22.3 | K18: 0.1 | L18: 5.5 | M18: 0 | N18: 0.05 | O18: 5.2 | P18: 150 | Q18: 150 | R18: 250 | S18: 350 | V18: =IF(Q18="","",J18*Q18/100) -> 33.45 | W18: =IF(R18="","",J18*R18/100) -> 55.75 | X18: =IF(S18="","",J18*S18/100) -> 78.05 | Y18: =IF(T18="","",J18*T18/100) | Z18: =IF(U18="","",J18*U18/100) | AA18: Medium | AB18: Typical-recipe estimate (IFCT 2017 / USDA FDC ingredient data) | AD18: =IF(AC18="","",IFERROR(INDEX('INDB Full Nutrients'!$D:$D,MATCH(AC18,'INDB Full Nutrients'!$A:$A,0)),""))
A19: D018 | B19: Nimbu pani - salted, no sugar | C19: Salted lemon water | D19: Cold Beverages & Sharbat | E19: Pan-India | F19: Veg | G19: Yes | H19: Beverage | I19: ml | J19: =4*K19+4*(L19-N19)+9*M19+2*N19 -> 3.5 | K19: 0.1 | L19: 0.8 | M19: 0 | N19: 0.05 | O19: 0.3 | P19: 200 | Q19: 150 | R19: 250 | S19: 350 | V19: =IF(Q19="","",J19*Q19/100) -> 5.25 | W19: =IF(R19="","",J19*R19/100) -> 8.75 | X19: =IF(S19="","",J19*S19/100) -> 12.25 | Y19: =IF(T19="","",J19*T19/100) | Z19: =IF(U19="","",J19*U19/100) | AA19: Medium | AB19: Typical-recipe estimate (IFCT 2017 / USDA FDC ingredient data) | AD19: =IF(AC19="","",IFERROR(INDEX('INDB Full Nutrients'!$D:$D,MATCH(AC19,'INDB Full Nutrients'!$A:$A,0)),""))
A20: D019 | B20: Lemon soda (sweet) | C20: Fresh lime soda sweet | D20: Cold Beverages & Sharbat | E20: Pan-India | F20: Veg | G20: Yes | H20: Beverage | I20: ml | J20: =4*K20+4*(L20-N20)+9*M20+2*N20 -> 28.4 | K20: 0.1 | L20: 7 | M20: 0 | N20: 0 | O20: 6.8 | P20: 50 | Q20: 150 | R20: 250 | S20: 350 | V20: =IF(Q20="","",J20*Q20/100) -> 42.6 | W20: =IF(R20="","",J20*R20/100) -> 71 | X20: =IF(S20="","",J20*S20/100) -> 99.4 | Y20: =IF(T20="","",J20*T20/100) | Z20: =IF(U20="","",J20*U20/100) | AA20: Medium | AB20: Typical-recipe estimate (IFCT 2017 / USDA FDC ingredient data) | AD20: =IF(AC20="","",IFERROR(INDEX('INDB Full Nutrients'!$D:$D,MATCH(AC20,'INDB Full Nutrients'!$A:$A,0)),""))
A21: D020 | B21: Jaljeera | C21: Jal jeera | D21: Cold Beverages & Sharbat | E21: North | F21: Veg | G21: Yes | H21: Beverage | I21: ml | J21: =4*K21+4*(L21-N21)+9*M21+2*N21 -> 25.5 | K21: 0.2 | L21: 6 | M21: 0.1 | N21: 0.1 | O21: 5 | P21: 300 | Q21: 150 | R21: 250 | S21: 350 | V21: =IF(Q21="","",J21*Q21/100) -> 38.25 | W21: =IF(R21="","",J21*R21/100) -> 63.75 | X21: =IF(S21="","",J21*S21/100) -> 89.25 | Y21: =IF(T21="","",J21*T21/100) | Z21: =IF(U21="","",J21*U21/100) | AA21: High | AB21: Agrees with INDB 2024 standard recipe (within 20%) | AC21: BFP024 | AD21: =IF(AC21="","",IFERROR(INDEX('INDB Full Nutrients'!$D:$D,MATCH(AC21,'INDB Full Nutrients'!$A:$A,0)),"")) -> 30.240807 | AE21: INDB 30 kcal/100 g (-16%)
A22: D021 | B22: Aam panna | C22: Raw mango drink | D22: Cold Beverages & Sharbat | E22: North | F22: Veg | G22: Yes | H22: Beverage | I22: ml | J22: =4*K22+4*(L22-N22)+9*M22+2*N22 -> 40.2 | K22: 0.2 | L22: 10 | M22: 0 | N22: 0.3 | O22: 8.5 | P22: 120 | Q22: 150 | R22: 250 | S22: 350 | V22: =IF(Q22="","",J22*Q22/100) -> 60.3 | W22: =IF(R22="","",J22*R22/100) -> 100.5 | X22: =IF(S22="","",J22*S22/100) -> 140.7 | Y22: =IF(T22="","",J22*T22/100) | Z22: =IF(U22="","",J22*U22/100) | AA22: High | AB22: Agrees with INDB 2024 standard recipe (within 20%) | AC22: ASC005 | AD22: =IF(AC22="","",IFERROR(INDEX('INDB Full Nutrients'!$D:$D,MATCH(AC22,'INDB Full Nutrients'!$A:$A,0)),"")) -> 35.918221 | AE22: INDB 36 kcal/100 g (+12%)
A23: D022 | B23: Kokum sharbat | C23: Kokum juice | D23: Cold Beverages & Sharbat | E23: West | F23: Veg | G23: Yes | H23: Beverage | I23: ml | J23: =4*K23+4*(L23-N23)+9*M23+2*N23 -> 44.4 | K23: 0.1 | L23: 11 | M23: 0 | N23: 0 | O23: 10.5 | P23: 60 | Q23: 150 | R23: 250 | S23: 350 | V23: =IF(Q23="","",J23*Q23/100) -> 66.6 | W23: =IF(R23="","",J23*R23/100) -> 111 | X23: =IF(S23="","",J23*S23/100) -> 155.4 | Y23: =IF(T23="","",J23*T23/100) | Z23: =IF(U23="","",J23*U23/100) | AA23: Medium | AB23: Typical-recipe estimate (IFCT 2017 / USDA FDC ingredient data) | AD23: =IF(AC23="","",IFERROR(INDEX('INDB Full Nutrients'!$D:$D,MATCH(AC23,'INDB Full Nutrients'!$A:$A,0)),""))
A24: D023 | B24: Bael sharbat | C24: Wood apple sharbat | D24: Cold Beverages & Sharbat | E24: North | F24: Veg | G24: Yes | H24: Beverage | I24: ml | J24: =4*K24+4*(L24-N24)+9*M24+2*N24 -> 37.7 | K24: 0.6 | L24: 9 | M24: 0.1 | N24: 0.8 | O24: 8 | P24: 5 | Q24: 150 | R24: 250 | S24: 350 | V24: =IF(Q24="","",J24*Q24/100) -> 56.55 | W24: =IF(R24="","",J24*R24/100) -> 94.25 | X24: =IF(S24="","",J24*S24/100) -> 131.95 | Y24: =IF(T24="","",J24*T24/100) | Z24: =IF(U24="","",J24*U24/100) | AA24: High | AB24: Agrees with INDB 2024 standard recipe (within 20%) | AC24: OSR001 | AD24: =IF(AC24="","",IFERROR(INDEX('INDB Full Nutrients'!$D:$D,MATCH(AC24,'INDB Full Nutrients'!$A:$A,0)),"")) -> 34.176884 | AE24: INDB 34 kcal/100 g (+10%)
A25: D024 | B25: Sattu sharbat (salted) | C25: Sattu drink | D25: Cold Beverages & Sharbat | E25: East | F25: Veg | G25: Yes | H25: Beverage | I25: ml | J25: =4*K25+4*(L25-N25)+9*M25+2*N25 -> 37.4 | K25: 2.2 | L25: 6.5 | M25: 0.6 | N25: 1.4 | O25: 0.5 | P25: 150 | Q25: 150 | R25: 250 | S25: 350 | V25: =IF(Q25="","",J25*Q25/100) -> 56.1 | W25: =IF(R25="","",J25*R25/100) -> 93.5 | X25: =IF(S25="","",J25*S25/100) -> 130.9 | Y25: =IF(T25="","",J25*T25/100) | Z25: =IF(U25="","",J25*U25/100) | AA25: Medium | AB25: Typical-recipe estimate (IFCT 2017 / USDA FDC ingredient data) | AC25: OSR002 | AD25: =IF(AC25="","",IFERROR(INDEX('INDB Full Nutrients'!$D:$D,MATCH(AC25,'INDB Full Nutrients'!$A:$A,0)),"")) -> 23.377426 | AE25: INDB 23 kcal/100 g (+60%) - INDB lower: lighter/thinner recipe, or cooking water counted in weight | AF25: ~2 tbsp sattu per glass
A26: D025 | B26: Rose sharbat / Rooh Afza (with water) | C26: Gulab sharbat | D26: Cold Beverages & Sharbat | E26: Pan-India | F26: Veg | G26: Yes | H26: Beverage | I26: ml | J26: =4*K26+4*(L26-N26)+9*M26+2*N26 -> 36 | K26: 0 | L26: 9 | M26: 0 | N26: 0 | O26: 9 | P26: 3 | Q26: 150 | R26: 250 | S26: 350 | V26: =IF(Q26="","",J26*Q26/100) -> 54 | W26: =IF(R26="","",J26*R26/100) -> 90 | X26: =IF(S26="","",J26*S26/100) -> 126 | Y26: =IF(T26="","",J26*T26/100) | Z26: =IF(U26="","",J26*U26/100) | AA26: Medium | AB26: Typical-recipe estimate (IFCT 2017 / USDA FDC ingredient data) | AD26: =IF(AC26="","",IFERROR(INDEX('INDB Full Nutrients'!$D:$D,MATCH(AC26,'INDB Full Nutrients'!$A:$A,0)),""))
A27: D026 | B27: Rooh Afza milk | C27: Rose milk (Rooh Afza) | D27: Cold Beverages & Sharbat | E27: North | F27: Veg | H27: Beverage | I27: ml | J27: =4*K27+4*(L27-N27)+9*M27+2*N27 -> 89 | K27: 3 | L27: 12.5 | M27: 3 | N27: 0 | O27: 12.5 | P27: 42 | Q27: 200 | R27: 300 | S27: 400 | V27: =IF(Q27="","",J27*Q27/100) -> 178 | W27: =IF(R27="","",J27*R27/100) -> 267 | X27: =IF(S27="","",J27*S27/100) -> 356 | Y27: =IF(T27="","",J27*T27/100) | Z27: =IF(U27="","",J27*U27/100) | AA27: Medium | AB27: Typical-recipe estimate (IFCT 2017 / USDA FDC ingredient data) | AD27: =IF(AC27="","",IFERROR(INDEX('INDB Full Nutrients'!$D:$D,MATCH(AC27,'INDB Full Nutrients'!$A:$A,0)),""))
A28: D027 | B28: Nannari sharbat | C28: Sarsaparilla sharbat | D28: Cold Beverages & Sharbat | E28: South | F28: Veg | G28: Yes | H28: Beverage | I28: ml | J28: =4*K28+4*(L28-N28)+9*M28+2*N28 -> 40 | K28: 0 | L28: 10 | M28: 0 | N28: 0 | O28: 10 | P28: 5 | Q28: 150 | R28: 250 | S28: 350 | V28: =IF(Q28="","",J28*Q28/100) -> 60 | W28: =IF(R28="","",J28*R28/100) -> 100 | X28: =IF(S28="","",J28*S28/100) -> 140 | Y28: =IF(T28="","",J28*T28/100) | Z28: =IF(U28="","",J28*U28/100) | AA28: Medium | AB28: Typical-recipe estimate (IFCT 2017 / USDA FDC ingredient data) | AC28: OSR008 | AD28: =IF(AC28="","",IFERROR(INDEX('INDB Full Nutrients'!$D:$D,MATCH(AC28,'INDB Full Nutrients'!$A:$A,0)),"")) -> 88.789841 | AE28: INDB 89 kcal/100 g (-55%) - INDB higher: cooking water likely not counted in weight, or more oil
A29: D028 | B29: Sol kadhi | C29: Kokum coconut milk drink | D29: Cold Beverages & Sharbat | E29: West | F29: Veg | G29: Yes | H29: Beverage | I29: ml | J29: =4*K29+4*(L29-N29)+9*M29+2*N29 -> 51.8 | K29: 0.6 | L29: 3.5 | M29: 4 | N29: 0.3 | O29: 2 | P29: 200 | Q29: 150 | R29: 250 | S29: 350 | V29: =IF(Q29="","",J29*Q29/100) -> 77.7 | W29: =IF(R29="","",J29*R29/100) -> 129.5 | X29: =IF(S29="","",J29*S29/100) -> 181.3 | Y29: =IF(T29="","",J29*T29/100) | Z29: =IF(U29="","",J29*U29/100) | AA29: Medium | AB29: Typical-recipe estimate (IFCT 2017 / USDA FDC ingredient data) | AD29: =IF(AC29="","",IFERROR(INDEX('INDB Full Nutrients'!$D:$D,MATCH(AC29,'INDB Full Nutrients'!$A:$A,0)),""))
A30: D029 | B30: Coconut water (tender coconut) | C30: Nariyal pani, elaneer | D30: Cold Beverages & Sharbat | E30: Pan-India | F30: Veg | G30: Yes | H30: Beverage | I30: ml | J30: =4*K30+4*(L30-N30)+9*M30+2*N30 -> 17.2 | K30: 0.7 | L30: 3.7 | M30: 0.2 | N30: 1.1 | O30: 2.6 | P30: 105 | Q30: 200 | R30: 300 | S30: 400 | V30: =IF(Q30="","",J30*Q30/100) -> 34.4 | W30: =IF(R30="","",J30*R30/100) -> 51.6 | X30: =IF(S30="","",J30*S30/100) -> 68.8 | Y30: =IF(T30="","",J30*T30/100) | Z30: =IF(U30="","",J30*U30/100) | AA30: High | AB30: Ingredient composition data (USDA FDC / IFCT 2017) | AD30: =IF(AC30="","",IFERROR(INDEX('INDB Full Nutrients'!$D:$D,MATCH(AC30,'INDB Full Nutrients'!$A:$A,0)),"")) | AF30: Natural, no sugar
A31: D030 | B31: Sugarcane juice | C31: Ganne ka ras, ganna juice | D31: Cold Beverages & Sharbat | E31: Pan-India | F31: Veg | G31: Yes | H31: Beverage | I31: ml | J31: =4*K31+4*(L31-N31)+9*M31+2*N31 -> 73.7 | K31: 0.2 | L31: 18 | M31: 0.1 | N31: 0 | O31: 16 | P31: 10 | Q31: 150 | R31: 250 | S31: 350 | V31: =IF(Q31="","",J31*Q31/100) -> 110.55 | W31: =IF(R31="","",J31*R31/100) -> 184.25 | X31: =IF(S31="","",J31*S31/100) -> 257.95 | Y31: =IF(T31="","",J31*T31/100) | Z31: =IF(U31="","",J31*U31/100) | AA31: High | AB31: Ingredient composition data (USDA FDC / IFCT 2017) | AD31: =IF(AC31="","",IFERROR(INDEX('INDB Full Nutrients'!$D:$D,MATCH(AC31,'INDB Full Nutrients'!$A:$A,0)),"")) | AF31: Fresh pressed; ~70-75 kcal/100 ml
A32: D031 | B32: Thandai | D32: Cold Beverages & Sharbat | E32: North | F32: Veg | H32: Beverage | I32: ml | J32: =4*K32+4*(L32-N32)+9*M32+2*N32 -> 112 | K32: 3.5 | L32: 13.5 | M32: 5 | N32: 0.5 | O32: 12 | P32: 40 | Q32: 150 | R32: 250 | S32: 350 | V32: =IF(Q32="","",J32*Q32/100) -> 168 | W32: =IF(R32="","",J32*R32/100) -> 280 | X32: =IF(S32="","",J32*S32/100) -> 392 | Y32: =IF(T32="","",J32*T32/100) | Z32: =IF(U32="","",J32*U32/100) | AA32: High | AB32: Agrees with INDB 2024 standard recipe (within 20%) | AC32: OSR005 | AD32: =IF(AC32="","",IFERROR(INDEX('INDB Full Nutrients'!$D:$D,MATCH(AC32,'INDB Full Nutrients'!$A:$A,0)),"")) -> 101.1769 | AE32: INDB 101 kcal/100 g (+11%) | AF32: Milk, nuts, seeds, sugar
A33: D032 | B33: Jigarthanda | C33: Madurai jigarthanda | D33: Cold Beverages & Sharbat | E33: South | F33: Veg | H33: Beverage | I33: ml | J33: =4*K33+4*(L33-N33)+9*M33+2*N33 -> 138.8 | K33: 3.5 | L33: 20 | M33: 5 | N33: 0.1 | O33: 18 | P33: 50 | Q33: 200 | R33: 300 | S33: 400 | V33: =IF(Q33="","",J33*Q33/100) -> 277.6 | W33: =IF(R33="","",J33*R33/100) -> 416.4 | X33: =IF(S33="","",J33*S33/100) -> 555.2 | Y33: =IF(T33="","",J33*T33/100) | Z33: =IF(U33="","",J33*U33/100) | AA33: Medium | AB33: Typical-recipe estimate (IFCT 2017 / USDA FDC ingredient data) | AD33: =IF(AC33="","",IFERROR(INDEX('INDB Full Nutrients'!$D:$D,MATCH(AC33,'INDB Full Nutrients'!$A:$A,0)),"")) | AF33: Milk, almond gum, nannari, ice cream
A34: D033 | B34: Falooda | C34: Royal falooda | D34: Cold Beverages & Sharbat | E34: Pan-India | F34: Veg | H34: Beverage | I34: ml | J34: =4*K34+4*(L34-N34)+9*M34+2*N34 -> 137.6 | K34: 3.2 | L34: 22 | M34: 4.2 | N34: 0.5 | O34: 17 | P34: 45 | Q34: 200 | R34: 300 | S34: 400 | V34: =IF(Q34="","",J34*Q34/100) -> 275.2 | W34: =IF(R34="","",J34*R34/100) -> 412.8 | X34: =IF(S34="","",J34*S34/100) -> 550.4 | Y34: =IF(T34="","",J34*T34/100) | Z34: =IF(U34="","",J34*U34/100) | AA34: Medium | AB34: Typical-recipe estimate (IFCT 2017 / USDA FDC ingredient data) | AD34: =IF(AC34="","",IFERROR(INDEX('INDB Full Nutrients'!$D:$D,MATCH(AC34,'INDB Full Nutrients'!$A:$A,0)),"")) | AF34: With ice cream, sabja, vermicelli, rose syrup
A35: D034 | B35: Rose milk | D35: Cold Beverages & Sharbat | E35: South | F35: Veg | H35: Beverage | I35: ml | J35: =4*K35+4*(L35-N35)+9*M35+2*N35 -> 91 | K35: 3 | L35: 13 | M35: 3 | N35: 0 | O35: 12.8 | P35: 42 | Q35: 200 | R35: 300 | S35: 400 | V35: =IF(Q35="","",J35*Q35/100) -> 182 | W35: =IF(R35="","",J35*R35/100) -> 273 | X35: =IF(S35="","",J35*S35/100) -> 364 | Y35: =IF(T35="","",J35*T35/100) | Z35: =IF(U35="","",J35*U35/100) | AA35: Medium | AB35: Typical-recipe estimate (IFCT 2017 / USDA FDC ingredient data) | AD35: =IF(AC35="","",IFERROR(INDEX('INDB Full Nutrients'!$D:$D,MATCH(AC35,'INDB Full Nutrients'!$A:$A,0)),""))
A36: D035 | B36: Cold coffee (milk + sugar) | D36: Cold Beverages & Sharbat | E36: Pan-India | F36: Veg | H36: Beverage | I36: ml | J36: =4*K36+4*(L36-N36)+9*M36+2*N36 -> 80.4 | K36: 2.8 | L36: 11 | M36: 2.8 | N36: 0 | O36: 11 | P36: 40 | Q36: 200 | R36: 300 | S36: 400 | V36: =IF(Q36="","",J36*Q36/100) -> 160.8 | W36: =IF(R36="","",J36*R36/100) -> 241.2 | X36: =IF(S36="","",J36*S36/100) -> 321.6 | Y36: =IF(T36="","",J36*T36/100) | Z36: =IF(U36="","",J36*U36/100) | AA36: High | AB36: Agrees with INDB 2024 standard recipe (within 20%) | AC36: BFP013 | AD36: =IF(AC36="","",IFERROR(INDEX('INDB Full Nutrients'!$D:$D,MATCH(AC36,'INDB Full Nutrients'!$A:$A,0)),"")) -> 82.764069 | AE36: INDB 83 kcal/100 g (-3%)
A37: D036 | B37: Cold coffee with ice cream | C37: Frappe | D37: Cold Beverages & Sharbat | E37: Pan-India | F37: Veg | H37: Beverage | I37: ml | J37: =4*K37+4*(L37-N37)+9*M37+2*N37 -> 112.5 | K37: 3 | L37: 15 | M37: 4.5 | N37: 0 | O37: 14.5 | P37: 45 | Q37: 200 | R37: 300 | S37: 400 | V37: =IF(Q37="","",J37*Q37/100) -> 225 | W37: =IF(R37="","",J37*R37/100) -> 337.5 | X37: =IF(S37="","",J37*S37/100) -> 450 | Y37: =IF(T37="","",J37*T37/100) | Z37: =IF(U37="","",J37*U37/100) | AA37: Medium | AB37: Typical-recipe estimate (IFCT 2017 / USDA FDC ingredient data) | AC37: ASC015 | AD37: =IF(AC37="","",IFERROR(INDEX('INDB Full Nutrients'!$D:$D,MATCH(AC37,'INDB Full Nutrients'!$A:$A,0)),"")) -> 67.848755 | AE37: INDB 68 kcal/100 g (+66%) - INDB lower: lighter/thinner recipe, or cooking water counted in weight
A38: D037 | B38: Soft drink / cola | C38: Coke, Thums Up, Pepsi | D38: Cold Beverages & Sharbat | E38: Pan-India | F38: Veg | G38: Yes | H38: Beverage | I38: ml | J38: =4*K38+4*(L38-N38)+9*M38+2*N38 -> 42.4 | K38: 0 | L38: 10.6 | M38: 0 | N38: 0 | O38: 10.6 | P38: 10 | Q38: 150 | R38: 250 | S38: 350 | V38: =IF(Q38="","",J38*Q38/100) -> 63.6 | W38: =IF(R38="","",J38*R38/100) -> 106 | X38: =IF(S38="","",J38*S38/100) -> 148.4 | Y38: =IF(T38="","",J38*T38/100) | Z38: =IF(U38="","",J38*U38/100) | AA38: High | AB38: Ingredient composition data (USDA FDC / IFCT 2017) | AD38: =IF(AC38="","",IFERROR(INDEX('INDB Full Nutrients'!$D:$D,MATCH(AC38,'INDB Full Nutrients'!$A:$A,0)),"")) | AF38: Regular, not diet
A39: D038 | B39: Packaged mango drink | C39: Frooti, Maaza, Slice | D39: Cold Beverages & Sharbat | E39: Pan-India | F39: Veg | G39: Yes | H39: Beverage | I39: ml | J39: =4*K39+4*(L39-N39)+9*M39+2*N39 -> 62.2 | K39: 0.1 | L39: 15.5 | M39: 0 | N39: 0.1 | O39: 15 | P39: 15 | Q39: 150 | R39: 250 | S39: 350 | V39: =IF(Q39="","",J39*Q39/100) -> 93.3 | W39: =IF(R39="","",J39*R39/100) -> 155.5 | X39: =IF(S39="","",J39*S39/100) -> 217.7 | Y39: =IF(T39="","",J39*T39/100) | Z39: =IF(U39="","",J39*U39/100) | AA39: Medium | AB39: Typical-recipe estimate (IFCT 2017 / USDA FDC ingredient data) | AD39: =IF(AC39="","",IFERROR(INDEX('INDB Full Nutrients'!$D:$D,MATCH(AC39,'INDB Full Nutrients'!$A:$A,0)),""))
A40: D039 | B40: Orange juice | C40: Santra/narangi juice | D40: Fruit Juices | E40: Pan-India | F40: Veg | G40: Yes | H40: Beverage | I40: ml | J40: =4*K40+4*(L40-N40)+9*M40+2*N40 -> 45.8 | K40: 0.7 | L40: 10.4 | M40: 0.2 | N40: 0.2 | O40: 8.4 | P40: 1 | Q40: 200 | R40: 300 | S40: 400 | V40: =IF(Q40="","",J40*Q40/100) -> 91.6 | W40: =IF(R40="","",J40*R40/100) -> 137.4 | X40: =IF(S40="","",J40*S40/100) -> 183.2 | Y40: =IF(T40="","",J40*T40/100) | Z40: =IF(U40="","",J40*U40/100) | AA40: High | AB40: Ingredient composition data (USDA FDC / IFCT 2017) | AD40: =IF(AC40="","",IFERROR(INDEX('INDB Full Nutrients'!$D:$D,MATCH(AC40,'INDB Full Nutrients'!$A:$A,0)),"")) | AF40: Fresh, no added sugar. Shop juices often add 2-4 tsp sugar/glass: +20 kcal & +5 g carbs per tsp
...

Sheet Portion Nutrition
A1: ID | B1: Dish | C1: Category | D1: Veg / Egg / Non-Veg | E1: Region | F1: Portion | G1: Portion description | H1: Quantity | I1: Unit | J1: Energy (kcal) | K1: Protein (g) | L1: Carbs (g) | M1: Fat (g) | N1: Fibre (g) | O1: Sugar (g) | P1: Sodium (mg)
A2: ='Dish Database'!A2 -> D001 | B2: ='Dish Database'!B2 -> Masala chai (milk + sugar) | C2: ='Dish Database'!D2 -> Hot Beverages | D2: ='Dish Database'!F2 -> Veg | E2: ='Dish Database'!E2 -> Pan-India | F2: Small | G2: Cutting / small cup (75 ml) | H2: 75 | I2: ='Dish Database'!I2 -> ml | J2: ='Dish Database'!J2*H2/100 -> 41.625 | K2: ='Dish Database'!K2*H2/100 -> 1.2 | L2: ='Dish Database'!L2*H2/100 -> 6.675 | M2: ='Dish Database'!M2*H2/100 -> 1.125 | N2: ='Dish Database'!N2*H2/100 -> 0 | O2: ='Dish Database'!O2*H2/100 -> 6.675 | P2: ='Dish Database'!P2*H2/100 -> 16.5
A3: ='Dish Database'!A2 -> D001 | B3: ='Dish Database'!B2 -> Masala chai (milk + sugar) | C3: ='Dish Database'!D2 -> Hot Beverages | D3: ='Dish Database'!F2 -> Veg | E3: ='Dish Database'!E2 -> Pan-India | F3: Medium | G3: 1 cup (150 ml) | H3: 150 | I3: ='Dish Database'!I2 -> ml | J3: ='Dish Database'!J2*H3/100 -> 83.25 | K3: ='Dish Database'!K2*H3/100 -> 2.4 | L3: ='Dish Database'!L2*H3/100 -> 13.35 | M3: ='Dish Database'!M2*H3/100 -> 2.25 | N3: ='Dish Database'!N2*H3/100 -> 0 | O3: ='Dish Database'!O2*H3/100 -> 13.35 | P3: ='Dish Database'!P2*H3/100 -> 33
A4: ='Dish Database'!A2 -> D001 | B4: ='Dish Database'!B2 -> Masala chai (milk + sugar) | C4: ='Dish Database'!D2 -> Hot Beverages | D4: ='Dish Database'!F2 -> Veg | E4: ='Dish Database'!E2 -> Pan-India | F4: Large | G4: Mug (250 ml) | H4: 250 | I4: ='Dish Database'!I2 -> ml | J4: ='Dish Database'!J2*H4/100 -> 138.75 | K4: ='Dish Database'!K2*H4/100 -> 4 | L4: ='Dish Database'!L2*H4/100 -> 22.25 | M4: ='Dish Database'!M2*H4/100 -> 3.75 | N4: ='Dish Database'!N2*H4/100 -> 0 | O4: ='Dish Database'!O2*H4/100 -> 22.25 | P4: ='Dish Database'!P2*H4/100 -> 55
A5: ='Dish Database'!A3 -> D002 | B5: ='Dish Database'!B3 -> Tea with milk, no sugar | C5: ='Dish Database'!D3 -> Hot Beverages | D5: ='Dish Database'!F3 -> Veg | E5: ='Dish Database'!E3 -> Pan-India | F5: Small | G5: Cutting / small cup (75 ml) | H5: 75 | I5: ='Dish Database'!I3 -> ml | J5: ='Dish Database'!J3*H5/100 -> 22.125 | K5: ='Dish Database'!K3*H5/100 -> 1.2 | L5: ='Dish Database'!L3*H5/100 -> 1.8 | M5: ='Dish Database'!M3*H5/100 -> 1.125 | N5: ='Dish Database'!N3*H5/100 -> 0 | O5: ='Dish Database'!O3*H5/100 -> 1.8 | P5: ='Dish Database'!P3*H5/100 -> 16.5
A6: ='Dish Database'!A3 -> D002 | B6: ='Dish Database'!B3 -> Tea with milk, no sugar | C6: ='Dish Database'!D3 -> Hot Beverages | D6: ='Dish Database'!F3 -> Veg | E6: ='Dish Database'!E3 -> Pan-India | F6: Medium | G6: 1 cup (150 ml) | H6: 150 | I6: ='Dish Database'!I3 -> ml | J6: ='Dish Database'!J3*H6/100 -> 44.25 | K6: ='Dish Database'!K3*H6/100 -> 2.4 | L6: ='Dish Database'!L3*H6/100 -> 3.6 | M6: ='Dish Database'!M3*H6/100 -> 2.25 | N6: ='Dish Database'!N3*H6/100 -> 0 | O6: ='Dish Database'!O3*H6/100 -> 3.6 | P6: ='Dish Database'!P3*H6/100 -> 33
A7: ='Dish Database'!A3 -> D002 | B7: ='Dish Database'!B3 -> Tea with milk, no sugar | C7: ='Dish Database'!D3 -> Hot Beverages | D7: ='Dish Database'!F3 -> Veg | E7: ='Dish Database'!E3 -> Pan-India | F7: Large | G7: Mug (250 ml) | H7: 250 | I7: ='Dish Database'!I3 -> ml | J7: ='Dish Database'!J3*H7/100 -> 73.75 | K7: ='Dish Database'!K3*H7/100 -> 4 | L7: ='Dish Database'!L3*H7/100 -> 6 | M7: ='Dish Database'!M3*H7/100 -> 3.75 | N7: ='Dish Database'!N3*H7/100 -> 0 | O7: ='Dish Database'!O3*H7/100 -> 6 | P7: ='Dish Database'!P3*H7/100 -> 55
A8: ='Dish Database'!A4 -> D003 | B8: ='Dish Database'!B4 -> Cutting chai (strong, extra milk & sugar) | C8: ='Dish Database'!D4 -> Hot Beverages | D8: ='Dish Database'!F4 -> Veg | E8: ='Dish Database'!E4 -> West | F8: Small | G8: Cutting / small cup (75 ml) | H8: 75 | I8: ='Dish Database'!I4 -> ml | J8: ='Dish Database'!J4*H8/100 -> 51 | K8: ='Dish Database'!K4*H8/100 -> 1.5 | L8: ='Dish Database'!L4*H8/100 -> 7.875 | M8: ='Dish Database'!M4*H8/100 -> 1.5 | N8: ='Dish Database'!N4*H8/100 -> 0 | O8: ='Dish Database'!O4*H8/100 -> 7.875 | P8: ='Dish Database'!P4*H8/100 -> 21
A9: ='Dish Database'!A4 -> D003 | B9: ='Dish Database'!B4 -> Cutting chai (strong, extra milk & sugar) | C9: ='Dish Database'!D4 -> Hot Beverages | D9: ='Dish Database'!F4 -> Veg | E9: ='Dish Database'!E4 -> West | F9: Medium | G9: 1 cup (150 ml) | H9: 150 | I9: ='Dish Database'!I4 -> ml | J9: ='Dish Database'!J4*H9/100 -> 102 | K9: ='Dish Database'!K4*H9/100 -> 3 | L9: ='Dish Database'!L4*H9/100 -> 15.75 | M9: ='Dish Database'!M4*H9/100 -> 3 | N9: ='Dish Database'!N4*H9/100 -> 0 | O9: ='Dish Database'!O4*H9/100 -> 15.75 | P9: ='Dish Database'!P4*H9/100 -> 42
A10: ='Dish Database'!A4 -> D003 | B10: ='Dish Database'!B4 -> Cutting chai (strong, extra milk & sugar) | C10: ='Dish Database'!D4 -> Hot Beverages | D10: ='Dish Database'!F4 -> Veg | E10: ='Dish Database'!E4 -> West | F10: Large | G10: Mug (250 ml) | H10: 250 | I10: ='Dish Database'!I4 -> ml | J10: ='Dish Database'!J4*H10/100 -> 170 | K10: ='Dish Database'!K4*H10/100 -> 5 | L10: ='Dish Database'!L4*H10/100 -> 26.25 | M10: ='Dish Database'!M4*H10/100 -> 5 | N10: ='Dish Database'!N4*H10/100 -> 0 | O10: ='Dish Database'!O4*H10/100 -> 26.25 | P10: ='Dish Database'!P4*H10/100 -> 70
A11: ='Dish Database'!A5 -> D004 | B11: ='Dish Database'!B5 -> Irani chai | C11: ='Dish Database'!D5 -> Hot Beverages | D11: ='Dish Database'!F5 -> Veg | E11: ='Dish Database'!E5 -> South | F11: Small | G11: Cutting / small cup (75 ml) | H11: 75 | I11: ='Dish Database'!I5 -> ml | J11: ='Dish Database'!J5*H11/100 -> 63.75 | K11: ='Dish Database'!K5*H11/100 -> 1.875 | L11: ='Dish Database'!L5*H11/100 -> 9 | M11: ='Dish Database'!M5*H11/100 -> 2.25 | N11: ='Dish Database'!N5*H11/100 -> 0 | O11: ='Dish Database'!O5*H11/100 -> 9 | P11: ='Dish Database'!P5*H11/100 -> 26.25
A12: ='Dish Database'!A5 -> D004 | B12: ='Dish Database'!B5 -> Irani chai | C12: ='Dish Database'!D5 -> Hot Beverages | D12: ='Dish Database'!F5 -> Veg | E12: ='Dish Database'!E5 -> South | F12: Medium | G12: 1 cup (150 ml) | H12: 150 | I12: ='Dish Database'!I5 -> ml | J12: ='Dish Database'!J5*H12/100 -> 127.5 | K12: ='Dish Database'!K5*H12/100 -> 3.75 | L12: ='Dish Database'!L5*H12/100 -> 18 | M12: ='Dish Database'!M5*H12/100 -> 4.5 | N12: ='Dish Database'!N5*H12/100 -> 0 | O12: ='Dish Database'!O5*H12/100 -> 18 | P12: ='Dish Database'!P5*H12/100 -> 52.5
A13: ='Dish Database'!A5 -> D004 | B13: ='Dish Database'!B5 -> Irani chai | C13: ='Dish Database'!D5 -> Hot Beverages | D13: ='Dish Database'!F5 -> Veg | E13: ='Dish Database'!E5 -> South | F13: Large | G13: Mug (250 ml) | H13: 250 | I13: ='Dish Database'!I5 -> ml | J13: ='Dish Database'!J5*H13/100 -> 212.5 | K13: ='Dish Database'!K5*H13/100 -> 6.25 | L13: ='Dish Database'!L5*H13/100 -> 30 | M13: ='Dish Database'!M5*H13/100 -> 7.5 | N13: ='Dish Database'!N5*H13/100 -> 0 | O13: ='Dish Database'!O5*H13/100 -> 30 | P13: ='Dish Database'!P5*H13/100 -> 87.5
A14: ='Dish Database'!A6 -> D005 | B14: ='Dish Database'!B6 -> Black tea, no sugar | C14: ='Dish Database'!D6 -> Hot Beverages | D14: ='Dish Database'!F6 -> Veg | E14: ='Dish Database'!E6 -> Pan-India | F14: Small | G14: Cutting / small cup (75 ml) | H14: 75 | I14: ='Dish Database'!I6 -> ml | J14: ='Dish Database'!J6*H14/100 -> 0.9 | K14: ='Dish Database'!K6*H14/100 -> 0 | L14: ='Dish Database'!L6*H14/100 -> 0.225 | M14: ='Dish Database'!M6*H14/100 -> 0 | N14: ='Dish Database'!N6*H14/100 -> 0 | O14: ='Dish Database'!O6*H14/100 -> 0 | P14: ='Dish Database'!P6*H14/100 -> 2.25
A15: ='Dish Database'!A6 -> D005 | B15: ='Dish Database'!B6 -> Black tea, no sugar | C15: ='Dish Database'!D6 -> Hot Beverages | D15: ='Dish Database'!F6 -> Veg | E15: ='Dish Database'!E6 -> Pan-India | F15: Medium | G15: 1 cup (150 ml) | H15: 150 | I15: ='Dish Database'!I6 -> ml | J15: ='Dish Database'!J6*H15/100 -> 1.8 | K15: ='Dish Database'!K6*H15/100 -> 0 | L15: ='Dish Database'!L6*H15/100 -> 0.45 | M15: ='Dish Database'!M6*H15/100 -> 0 | N15: ='Dish Database'!N6*H15/100 -> 0 | O15: ='Dish Database'!O6*H15/100 -> 0 | P15: ='Dish Database'!P6*H15/100 -> 4.5
A16: ='Dish Database'!A6 -> D005 | B16: ='Dish Database'!B6 -> Black tea, no sugar | C16: ='Dish Database'!D6 -> Hot Beverages | D16: ='Dish Database'!F6 -> Veg | E16: ='Dish Database'!E6 -> Pan-India | F16: Large | G16: Mug (250 ml) | H16: 250 | I16: ='Dish Database'!I6 -> ml | J16: ='Dish Database'!J6*H16/100 -> 3 | K16: ='Dish Database'!K6*H16/100 -> 0 | L16: ='Dish Database'!L6*H16/100 -> 0.75 | M16: ='Dish Database'!M6*H16/100 -> 0 | N16: ='Dish Database'!N6*H16/100 -> 0 | O16: ='Dish Database'!O6*H16/100 -> 0 | P16: ='Dish Database'!P6*H16/100 -> 7.5
A17: ='Dish Database'!A7 -> D006 | B17: ='Dish Database'!B7 -> Lemon tea with sugar | C17: ='Dish Database'!D7 -> Hot Beverages | D17: ='Dish Database'!F7 -> Veg | E17: ='Dish Database'!E7 -> Pan-India | F17: Small | G17: Cutting / small cup (75 ml) | H17: 75 | I17: ='Dish Database'!I7 -> ml | J17: ='Dish Database'!J7*H17/100 -> 15 | K17: ='Dish Database'!K7*H17/100 -> 0 | L17: ='Dish Database'!L7*H17/100 -> 3.75 | M17: ='Dish Database'!M7*H17/100 -> 0 | N17: ='Dish Database'!N7*H17/100 -> 0 | O17: ='Dish Database'!O7*H17/100 -> 3.75 | P17: ='Dish Database'!P7*H17/100 -> 2.25
A18: ='Dish Database'!A7 -> D006 | B18: ='Dish Database'!B7 -> Lemon tea with sugar | C18: ='Dish Database'!D7 -> Hot Beverages | D18: ='Dish Database'!F7 -> Veg | E18: ='Dish Database'!E7 -> Pan-India | F18: Medium | G18: 1 cup (150 ml) | H18: 150 | I18: ='Dish Database'!I7 -> ml | J18: ='Dish Database'!J7*H18/100 -> 30 | K18: ='Dish Database'!K7*H18/100 -> 0 | L18: ='Dish Database'!L7*H18/100 -> 7.5 | M18: ='Dish Database'!M7*H18/100 -> 0 | N18: ='Dish Database'!N7*H18/100 -> 0 | O18: ='Dish Database'!O7*H18/100 -> 7.5 | P18: ='Dish Database'!P7*H18/100 -> 4.5
A19: ='Dish Database'!A7 -> D006 | B19: ='Dish Database'!B7 -> Lemon tea with sugar | C19: ='Dish Database'!D7 -> Hot Beverages | D19: ='Dish Database'!F7 -> Veg | E19: ='Dish Database'!E7 -> Pan-India | F19: Large | G19: Mug (250 ml) | H19: 250 | I19: ='Dish Database'!I7 -> ml | J19: ='Dish Database'!J7*H19/100 -> 50 | K19: ='Dish Database'!K7*H19/100 -> 0 | L19: ='Dish Database'!L7*H19/100 -> 12.5 | M19: ='Dish Database'!M7*H19/100 -> 0 | N19: ='Dish Database'!N7*H19/100 -> 0 | O19: ='Dish Database'!O7*H19/100 -> 12.5 | P19: ='Dish Database'!P7*H19/100 -> 7.5
A20: ='Dish Database'!A8 -> D007 | B20: ='Dish Database'!B8 -> Green tea, no sugar | C20: ='Dish Database'!D8 -> Hot Beverages | D20: ='Dish Database'!F8 -> Veg | E20: ='Dish Database'!E8 -> Pan-India | F20: Small | G20: Cutting / small cup (75 ml) | H20: 75 | I20: ='Dish Database'!I8 -> ml | J20: ='Dish Database'!J8*H20/100 -> 0.6 | K20: ='Dish Database'!K8*H20/100 -> 0.15 | L20: ='Dish Database'!L8*H20/100 -> 0 | M20: ='Dish Database'!M8*H20/100 -> 0 | N20: ='Dish Database'!N8*H20/100 -> 0 | O20: ='Dish Database'!O8*H20/100 -> 0 | P20: ='Dish Database'!P8*H20/100 -> 0.75
A21: ='Dish Database'!A8 -> D007 | B21: ='Dish Database'!B8 -> Green tea, no sugar | C21: ='Dish Database'!D8 -> Hot Beverages | D21: ='Dish Database'!F8 -> Veg | E21: ='Dish Database'!E8 -> Pan-India | F21: Medium | G21: 1 cup (150 ml) | H21: 150 | I21: ='Dish Database'!I8 -> ml | J21: ='Dish Database'!J8*H21/100 -> 1.2 | K21: ='Dish Database'!K8*H21/100 -> 0.3 | L21: ='Dish Database'!L8*H21/100 -> 0 | M21: ='Dish Database'!M8*H21/100 -> 0 | N21: ='Dish Database'!N8*H21/100 -> 0 | O21: ='Dish Database'!O8*H21/100 -> 0 | P21: ='Dish Database'!P8*H21/100 -> 1.5
A22: ='Dish Database'!A8 -> D007 | B22: ='Dish Database'!B8 -> Green tea, no sugar | C22: ='Dish Database'!D8 -> Hot Beverages | D22: ='Dish Database'!F8 -> Veg | E22: ='Dish Database'!E8 -> Pan-India | F22: Large | G22: Mug (250 ml) | H22: 250 | I22: ='Dish Database'!I8 -> ml | J22: ='Dish Database'!J8*H22/100 -> 2 | K22: ='Dish Database'!K8*H22/100 -> 0.5 | L22: ='Dish Database'!L8*H22/100 -> 0 | M22: ='Dish Database'!M8*H22/100 -> 0 | N22: ='Dish Database'!N8*H22/100 -> 0 | O22: ='Dish Database'!O8*H22/100 -> 0 | P22: ='Dish Database'!P8*H22/100 -> 2.5
A23: ='Dish Database'!A9 -> D008 | B23: ='Dish Database'!B9 -> South Indian filter coffee (milk + sugar) | C23: ='Dish Database'!D9 -> Hot Beverages | D23: ='Dish Database'!F9 -> Veg | E23: ='Dish Database'!E9 -> South | F23: Small | G23: Cutting / small cup (75 ml) | H23: 75 | I23: ='Dish Database'!I9 -> ml | J23: ='Dish Database'!J9*H23/100 -> 53.175 | K23: ='Dish Database'!K9*H23/100 -> 1.95 | L23: ='Dish Database'!L9*H23/100 -> 7.125 | M23: ='Dish Database'!M9*H23/100 -> 1.875 | N23: ='Dish Database'!N9*H23/100 -> 0 | O23: ='Dish Database'!O9*H23/100 -> 7.125 | P23: ='Dish Database'!P9*H23/100 -> 26.25
A24: ='Dish Database'!A9 -> D008 | B24: ='Dish Database'!B9 -> South Indian filter coffee (milk + sugar) | C24: ='Dish Database'!D9 -> Hot Beverages | D24: ='Dish Database'!F9 -> Veg | E24: ='Dish Database'!E9 -> South | F24: Medium | G24: 1 cup (150 ml) | H24: 150 | I24: ='Dish Database'!I9 -> ml | J24: ='Dish Database'!J9*H24/100 -> 106.35 | K24: ='Dish Database'!K9*H24/100 -> 3.9 | L24: ='Dish Database'!L9*H24/100 -> 14.25 | M24: ='Dish Database'!M9*H24/100 -> 3.75 | N24: ='Dish Database'!N9*H24/100 -> 0 | O24: ='Dish Database'!O9*H24/100 -> 14.25 | P24: ='Dish Database'!P9*H24/100 -> 52.5
A25: ='Dish Database'!A9 -> D008 | B25: ='Dish Database'!B9 -> South Indian filter coffee (milk + sugar) | C25: ='Dish Database'!D9 -> Hot Beverages | D25: ='Dish Database'!F9 -> Veg | E25: ='Dish Database'!E9 -> South | F25: Large | G25: Mug (250 ml) | H25: 250 | I25: ='Dish Database'!I9 -> ml | J25: ='Dish Database'!J9*H25/100 -> 177.25 | K25: ='Dish Database'!K9*H25/100 -> 6.5 | L25: ='Dish Database'!L9*H25/100 -> 23.75 | M25: ='Dish Database'!M9*H25/100 -> 6.25 | N25: ='Dish Database'!N9*H25/100 -> 0 | O25: ='Dish Database'!O9*H25/100 -> 23.75 | P25: ='Dish Database'!P9*H25/100 -> 87.5
A26: ='Dish Database'!A10 -> D009 | B26: ='Dish Database'!B10 -> Instant coffee with milk & sugar | C26: ='Dish Database'!D10 -> Hot Beverages | D26: ='Dish Database'!F10 -> Veg | E26: ='Dish Database'!E10 -> Pan-India | F26: Small | G26: Cutting / small cup (75 ml) | H26: 75 | I26: ='Dish Database'!I10 -> ml | J26: ='Dish Database'!J10*H26/100 -> 55.8 | K26: ='Dish Database'!K10*H26/100 -> 2.1 | L26: ='Dish Database'!L10*H26/100 -> 7.125 | M26: ='Dish Database'!M10*H26/100 -> 2.1 | N26: ='Dish Database'!N10*H26/100 -> 0 | O26: ='Dish Database'!O10*H26/100 -> 7.125 | P26: ='Dish Database'!P10*H26/100 -> 30
A27: ='Dish Database'!A10 -> D009 | B27: ='Dish Database'!B10 -> Instant coffee with milk & sugar | C27: ='Dish Database'!D10 -> Hot Beverages | D27: ='Dish Database'!F10 -> Veg | E27: ='Dish Database'!E10 -> Pan-India | F27: Medium | G27: 1 cup (150 ml) | H27: 150 | I27: ='Dish Database'!I10 -> ml | J27: ='Dish Database'!J10*H27/100 -> 111.6 | K27: ='Dish Database'!K10*H27/100 -> 4.2 | L27: ='Dish Database'!L10*H27/100 -> 14.25 | M27: ='Dish Database'!M10*H27/100 -> 4.2 | N27: ='Dish Database'!N10*H27/100 -> 0 | O27: ='Dish Database'!O10*H27/100 -> 14.25 | P27: ='Dish Database'!P10*H27/100 -> 60
A28: ='Dish Database'!A10 -> D009 | B28: ='Dish Database'!B10 -> Instant coffee with milk & sugar | C28: ='Dish Database'!D10 -> Hot Beverages | D28: ='Dish Database'!F10 -> Veg | E28: ='Dish Database'!E10 -> Pan-India | F28: Large | G28: Mug (250 ml) | H28: 250 | I28: ='Dish Database'!I10 -> ml | J28: ='Dish Database'!J10*H28/100 -> 186 | K28: ='Dish Database'!K10*H28/100 -> 7 | L28: ='Dish Database'!L10*H28/100 -> 23.75 | M28: ='Dish Database'!M10*H28/100 -> 7 | N28: ='Dish Database'!N10*H28/100 -> 0 | O28: ='Dish Database'!O10*H28/100 -> 23.75 | P28: ='Dish Database'!P10*H28/100 -> 100
A29: ='Dish Database'!A11 -> D010 | B29: ='Dish Database'!B11 -> Black coffee, no sugar | C29: ='Dish Database'!D11 -> Hot Beverages | D29: ='Dish Database'!F11 -> Veg | E29: ='Dish Database'!E11 -> Pan-India | F29: Small | G29: Cutting / small cup (75 ml) | H29: 75 | I29: ='Dish Database'!I11 -> ml | J29: ='Dish Database'!J11*H29/100 -> 0.6 | K29: ='Dish Database'!K11*H29/100 -> 0.075 | L29: ='Dish Database'!L11*H29/100 -> 0.075 | M29: ='Dish Database'!M11*H29/100 -> 0 | N29: ='Dish Database'!N11*H29/100 -> 0 | O29: ='Dish Database'!O11*H29/100 -> 0 | P29: ='Dish Database'!P11*H29/100 -> 1.5
A30: ='Dish Database'!A11 -> D010 | B30: ='Dish Database'!B11 -> Black coffee, no sugar | C30: ='Dish Database'!D11 -> Hot Beverages | D30: ='Dish Database'!F11 -> Veg | E30: ='Dish Database'!E11 -> Pan-India | F30: Medium | G30: 1 cup (150 ml) | H30: 150 | I30: ='Dish Database'!I11 -> ml | J30: ='Dish Database'!J11*H30/100 -> 1.2 | K30: ='Dish Database'!K11*H30/100 -> 0.15 | L30: ='Dish Database'!L11*H30/100 -> 0.15 | M30: ='Dish Database'!M11*H30/100 -> 0 | N30: ='Dish Database'!N11*H30/100 -> 0 | O30: ='Dish Database'!O11*H30/100 -> 0 | P30: ='Dish Database'!P11*H30/100 -> 3
A31: ='Dish Database'!A11 -> D010 | B31: ='Dish Database'!B11 -> Black coffee, no sugar | C31: ='Dish Database'!D11 -> Hot Beverages | D31: ='Dish Database'!F11 -> Veg | E31: ='Dish Database'!E11 -> Pan-India | F31: Large | G31: Mug (250 ml) | H31: 250 | I31: ='Dish Database'!I11 -> ml | J31: ='Dish Database'!J11*H31/100 -> 2 | K31: ='Dish Database'!K11*H31/100 -> 0.25 | L31: ='Dish Database'!L11*H31/100 -> 0.25 | M31: ='Dish Database'!M11*H31/100 -> 0 | N31: ='Dish Database'!N11*H31/100 -> 0 | O31: ='Dish Database'!O11*H31/100 -> 0 | P31: ='Dish Database'!P11*H31/100 -> 5
A32: ='Dish Database'!A12 -> D011 | B32: ='Dish Database'!B12 -> Hot chocolate / cocoa milk | C32: ='Dish Database'!D12 -> Hot Beverages | D32: ='Dish Database'!F12 -> Veg | E32: ='Dish Database'!E12 -> Pan-India | F32: Small | G32: Cutting / small cup (75 ml) | H32: 75 | I32: ='Dish Database'!I12 -> ml | J32: ='Dish Database'!J12*H32/100 -> 69.825 | K32: ='Dish Database'!K12*H32/100 -> 2.4 | L32: ='Dish Database'!L12*H32/100 -> 9.375 | M32: ='Dish Database'!M12*H32/100 -> 2.625 | N32: ='Dish Database'!N12*H32/100 -> 0.45 | O32: ='Dish Database'!O12*H32/100 -> 8.25 | P32: ='Dish Database'!P12*H32/100 -> 37.5
A33: ='Dish Database'!A12 -> D011 | B33: ='Dish Database'!B12 -> Hot chocolate / cocoa milk | C33: ='Dish Database'!D12 -> Hot Beverages | D33: ='Dish Database'!F12 -> Veg | E33: ='Dish Database'!E12 -> Pan-India | F33: Medium | G33: 1 cup (150 ml) | H33: 150 | I33: ='Dish Database'!I12 -> ml | J33: ='Dish Database'!J12*H33/100 -> 139.65 | K33: ='Dish Database'!K12*H33/100 -> 4.8 | L33: ='Dish Database'!L12*H33/100 -> 18.75 | M33: ='Dish Database'!M12*H33/100 -> 5.25 | N33: ='Dish Database'!N12*H33/100 -> 0.9 | O33: ='Dish Database'!O12*H33/100 -> 16.5 | P33: ='Dish Database'!P12*H33/100 -> 75
A34: ='Dish Database'!A12 -> D011 | B34: ='Dish Database'!B12 -> Hot chocolate / cocoa milk | C34: ='Dish Database'!D12 -> Hot Beverages | D34: ='Dish Database'!F12 -> Veg | E34: ='Dish Database'!E12 -> Pan-India | F34: Large | G34: Mug (250 ml) | H34: 250 | I34: ='Dish Database'!I12 -> ml | J34: ='Dish Database'!J12*H34/100 -> 232.75 | K34: ='Dish Database'!K12*H34/100 -> 8 | L34: ='Dish Database'!L12*H34/100 -> 31.25 | M34: ='Dish Database'!M12*H34/100 -> 8.75 | N34: ='Dish Database'!N12*H34/100 -> 1.5 | O34: ='Dish Database'!O12*H34/100 -> 27.5 | P34: ='Dish Database'!P12*H34/100 -> 125
A35: ='Dish Database'!A13 -> D012 | B35: ='Dish Database'!B13 -> Haldi doodh (turmeric milk) | C35: ='Dish Database'!D13 -> Hot Beverages | D35: ='Dish Database'!F13 -> Veg | E35: ='Dish Database'!E13 -> Pan-India | F35: Small | G35: Small glass (150 ml) | H35: 150 | I35: ='Dish Database'!I13 -> ml | J35: ='Dish Database'!J13*H35/100 -> 110.1 | K35: ='Dish Database'!K13*H35/100 -> 4.8 | L35: ='Dish Database'!L13*H35/100 -> 11.25 | M35: ='Dish Database'!M13*H35/100 -> 5.1 | N35: ='Dish Database'!N13*H35/100 -> 0 | O35: ='Dish Database'!O13*H35/100 -> 10.95 | P35: ='Dish Database'!P13*H35/100 -> 64.5
A36: ='Dish Database'!A13 -> D012 | B36: ='Dish Database'!B13 -> Haldi doodh (turmeric milk) | C36: ='Dish Database'!D13 -> Hot Beverages | D36: ='Dish Database'!F13 -> Veg | E36: ='Dish Database'!E13 -> Pan-India | F36: Medium | G36: 1 glass (200 ml) | H36: 200 | I36: ='Dish Database'!I13 -> ml | J36: ='Dish Database'!J13*H36/100 -> 146.8 | K36: ='Dish Database'!K13*H36/100 -> 6.4 | L36: ='Dish Database'!L13*H36/100 -> 15 | M36: ='Dish Database'!M13*H36/100 -> 6.8 | N36: ='Dish Database'!N13*H36/100 -> 0 | O36: ='Dish Database'!O13*H36/100 -> 14.6 | P36: ='Dish Database'!P13*H36/100 -> 86
A37: ='Dish Database'!A13 -> D012 | B37: ='Dish Database'!B13 -> Haldi doodh (turmeric milk) | C37: ='Dish Database'!D13 -> Hot Beverages | D37: ='Dish Database'!F13 -> Veg | E37: ='Dish Database'!E13 -> Pan-India | F37: Large | G37: Large glass (300 ml) | H37: 300 | I37: ='Dish Database'!I13 -> ml | J37: ='Dish Database'!J13*H37/100 -> 220.2 | K37: ='Dish Database'!K13*H37/100 -> 9.6 | L37: ='Dish Database'!L13*H37/100 -> 22.5 | M37: ='Dish Database'!M13*H37/100 -> 10.2 | N37: ='Dish Database'!N13*H37/100 -> 0 | O37: ='Dish Database'!O13*H37/100 -> 21.9 | P37: ='Dish Database'!P13*H37/100 -> 129
A38: ='Dish Database'!A14 -> D013 | B38: ='Dish Database'!B14 -> Badam milk (hot or cold) | C38: ='Dish Database'!D14 -> Hot Beverages | D38: ='Dish Database'!F14 -> Veg | E38: ='Dish Database'!E14 -> South | F38: Small | G38: Small glass (150 ml) | H38: 150 | I38: ='Dish Database'!I14 -> ml | J38: ='Dish Database'!J14*H38/100 -> 154.35 | K38: ='Dish Database'!K14*H38/100 -> 5.7 | L38: ='Dish Database'!L14*H38/100 -> 18 | M38: ='Dish Database'!M14*H38/100 -> 6.75 | N38: ='Dish Database'!N14*H38/100 -> 0.6 | O38: ='Dish Database'!O14*H38/100 -> 17.25 | P38: ='Dish Database'!P14*H38/100 -> 63
A39: ='Dish Database'!A14 -> D013 | B39: ='Dish Database'!B14 -> Badam milk (hot or cold) | C39: ='Dish Database'!D14 -> Hot Beverages | D39: ='Dish Database'!F14 -> Veg | E39: ='Dish Database'!E14 -> South | F39: Medium | G39: 1 glass (200 ml) | H39: 200 | I39: ='Dish Database'!I14 -> ml | J39: ='Dish Database'!J14*H39/100 -> 205.8 | K39: ='Dish Database'!K14*H39/100 -> 7.6 | L39: ='Dish Database'!L14*H39/100 -> 24 | M39: ='Dish Database'!M14*H39/100 -> 9 | N39: ='Dish Database'!N14*H39/100 -> 0.8 | O39: ='Dish Database'!O14*H39/100 -> 23 | P39: ='Dish Database'!P14*H39/100 -> 84
A40: ='Dish Database'!A14 -> D013 | B40: ='Dish Database'!B14 -> Badam milk (hot or cold) | C40: ='Dish Database'!D14 -> Hot Beverages | D40: ='Dish Database'!F14 -> Veg | E40: ='Dish Database'!E14 -> South | F40: Large | G40: Large glass (300 ml) | H40: 300 | I40: ='Dish Database'!I14 -> ml | J40: ='Dish Database'!J14*H40/100 -> 308.7 | K40: ='Dish Database'!K14*H40/100 -> 11.4 | L40: ='Dish Database'!L14*H40/100 -> 36 | M40: ='Dish Database'!M14*H40/100 -> 13.5 | N40: ='Dish Database'!N14*H40/100 -> 1.2 | O40: ='Dish Database'!O14*H40/100 -> 34.5 | P40: ='Dish Database'!P14*H40/100 -> 126
...

Sheet Meal Combos & Thalis
A1: Meal / combo | B1: Item | C1: Dish ID | D1: Quantity (g/ml) | E1: Energy (kcal) | F1: Protein (g) | G1: Carbs (g) | H1: Fat (g) | I1: Fibre (g) | J1: Sugar (g) | K1: Sodium (mg)
A2: Idli sambar (2 idli)
B3: =INDEX('Dish Database'!$B:$B,MATCH(C3,'Dish Database'!$A:$A,0)) -> Idli | C3: D138 | D3: 80 | E3: =D3/100*INDEX('Dish Database'!$J:$J,MATCH(C3,'Dish Database'!$A:$A,0)) -> 106 | F3: =D3/100*INDEX('Dish Database'!$K:$K,MATCH(C3,'Dish Database'!$A:$A,0)) -> 3.36 | G3: =D3/100*INDEX('Dish Database'!$L:$L,MATCH(C3,'Dish Database'!$A:$A,0)) -> 22.8 | H3: =D3/100*INDEX('Dish Database'!$M:$M,MATCH(C3,'Dish Database'!$A:$A,0)) -> 0.4 | I3: =D3/100*INDEX('Dish Database'!$N:$N,MATCH(C3,'Dish Database'!$A:$A,0)) -> 1.12 | J3: =D3/100*INDEX('Dish Database'!$O:$O,MATCH(C3,'Dish Database'!$A:$A,0)) -> 0.16 | K3: =D3/100*INDEX('Dish Database'!$P:$P,MATCH(C3,'Dish Database'!$A:$A,0)) -> 200
B4: =INDEX('Dish Database'!$B:$B,MATCH(C4,'Dish Database'!$A:$A,0)) -> Sambar | C4: D250 | D4: 150 | E4: =D4/100*INDEX('Dish Database'!$J:$J,MATCH(C4,'Dish Database'!$A:$A,0)) -> 114 | F4: =D4/100*INDEX('Dish Database'!$K:$K,MATCH(C4,'Dish Database'!$A:$A,0)) -> 5.25 | G4: =D4/100*INDEX('Dish Database'!$L:$L,MATCH(C4,'Dish Database'!$A:$A,0)) -> 15.75 | H4: =D4/100*INDEX('Dish Database'!$M:$M,MATCH(C4,'Dish Database'!$A:$A,0)) -> 4.2 | I4: =D4/100*INDEX('Dish Database'!$N:$N,MATCH(C4,'Dish Database'!$A:$A,0)) -> 3.9 | J4: =D4/100*INDEX('Dish Database'!$O:$O,MATCH(C4,'Dish Database'!$A:$A,0)) -> 3 | K4: =D4/100*INDEX('Dish Database'!$P:$P,MATCH(C4,'Dish Database'!$A:$A,0)) -> 495
B5: =INDEX('Dish Database'!$B:$B,MATCH(C5,'Dish Database'!$A:$A,0)) -> Coconut chutney | C5: D492 | D5: 30 | E5: =D5/100*INDEX('Dish Database'!$J:$J,MATCH(C5,'Dish Database'!$A:$A,0)) -> 65.25 | F5: =D5/100*INDEX('Dish Database'!$K:$K,MATCH(C5,'Dish Database'!$A:$A,0)) -> 1.05 | G5: =D5/100*INDEX('Dish Database'!$L:$L,MATCH(C5,'Dish Database'!$A:$A,0)) -> 3.6 | H5: =D5/100*INDEX('Dish Database'!$M:$M,MATCH(C5,'Dish Database'!$A:$A,0)) -> 5.55 | I5: =D5/100*INDEX('Dish Database'!$N:$N,MATCH(C5,'Dish Database'!$A:$A,0)) -> 1.65 | J5: =D5/100*INDEX('Dish Database'!$O:$O,MATCH(C5,'Dish Database'!$A:$A,0)) -> 0.75 | K5: =D5/100*INDEX('Dish Database'!$P:$P,MATCH(C5,'Dish Database'!$A:$A,0)) -> 90
B6: TOTAL | D6: =SUM(D3:D5) -> 260 | E6: =SUM(E3:E5) -> 285.25 | F6: =SUM(F3:F5) -> 9.66 | G6: =SUM(G3:G5) -> 42.15 | H6: =SUM(H3:H5) -> 10.15 | I6: =SUM(I3:I5) -> 6.67 | J6: =SUM(J3:J5) -> 3.91 | K6: =SUM(K3:K5) -> 785
A8: Masala dosa with sambar & chutney
